# 47. 에러 처리

## 47.1 에러 처리의 필요성

- 에러나 예외적인 상황이 발생하지 않는 코드 작성하는 것은 불가능하고, 에러에 대처하지 않고 방치하면 프로그램이 강제 종료되기 때문
- 따라서 적절하게 에러 처리를 하여 프로그램 강.종 되지 않도록 할 필요가 있음

## 47.2 try...catch...finally 문

- 에러 처리의 두 가지 방식
  1.  예외 상황이 발생하면 반환하는 값(null or -1과 같은 값)을 조건문, 옵셔널 체이닝 연산자, 단축 평가 등을 통해 처리하는 방법
  2.  에러 처리 코드를 작성하고 에러 발생하면 에러 처리 코드로 점프하도록 하는 방법
- `try...catch...finally` 는 두 번째 방식이고 보통 이 방식을 에러 처리라고 함

```js
try {
  // 실행할 코드 (에러가 발생할 가능성이 있는 코드)
} catch (error) {
  // try 코드 블록에서 에러가 발생하면 이 코드 블록의 코드가 실행됨
  // error에는 try 코드 블록에서 발생한 Error 객체가 전달됨
} finally {
  // 에러 발생과 상관없이 반드시 한 번 실행
}
```

## 47.3 Error 객체

- Error 생성자 함수는 에러 객체를 생성함
  - 에러를 상세히 설명하는 여러 메시지를 인수로 전달 가능

```js
const error = new Error('invalid');
```

- Error 객체
  - message 프로퍼티: 생성자 함수에 인수로 전달한 에러 메시지
  - stack 프로퍼티: 에러를 발생시킨 콜 스택의 호출 정보를 나타내는 문자열 => 디버깅 목적으로 사용

| 생성자 함수    | 인스턴스                                                                       |
| -------------- | ------------------------------------------------------------------------------ |
| Error          | 일반적 에러 객체                                                               |
| SyntaxError    | 자바스크립트 문법에 맞지 않는 문을 해석할 때 발생하는 에러 객체                |
| ReferenceError | 참조할 수 없는 식별자를 참조했을 때 발생하는 에러 객체                         |
| TypeError      | 피연산자 또는 인수의 데이터 타입이 유효하지 않을 때 발생하는 에러 객체         |
| RangeError     | 숫자값의 허용 범위를 벗어났을 때 발생하는 에러 객체                            |
| URIError       | encodeURI 또는 decodeURI 함수에 부적절한 인수를 전달했을 때 발생하는 에러 객체 |
| EvalError      | eval 함수에서 발생하는 에러 객체                                               |
|                |

```js
1 @ 1;    // SyntaxError: Invalid or unexpected token
foo();    // ReferenceError: foo is not defined
null.foo; // TypeError: Cannot read property 'foo' of null
new Array(-1); // RangeError: Invalid array length
decodeURIComponent('%'); // URIError: URI malformed
```

## 47.4 throw 문

- Error 생서앚 함수로 에러 객체를 생성한다고 에러가 발생하는 것은 아님

```js
try {
  // 에러 객체를 생성한다고 에러가 발생하는 것은 아니다.
  new Error('something wrong');
} catch (error) {
  console.log(error);
}
```

- 에러를 발생시키려면 try 코드 블록에서 throw 문으로 에러 객체를 던져야 함

```js
try {
  // 에러 객체를 던지면 catch 코드 블록이 실행되기 시작한다.
  throw new Error('something wrong');
} catch (error) {
  console.log(error);
}
```

- 예시: f 매개 변수로 전달받은 값이 함수가 아니라면 에러를 발생시킴

```js
// 외부에서 전달받은 콜백 함수를 n번만큼 반복 호출한다
const repeat = (n, f) => {
  // 매개변수 f에 전달된 인수가 함수가 아니면 TypeError를 발생시킨다.
  if (typeof f !== 'function') throw new TypeError('f must be a function');

  for (var i = 0; i < n; i++) {
    f(i); // i를 전달하면서 f를 호출
  }
};

try {
  repeat(2, 1); // 두 번째 인수가 함수가 아니므로 TypeError가 발생(throw)한다.
} catch (err) {
  console.error(err); // TypeError: f must be a function
}
```

## 47.5 에러의 전파

- 에러는 호출자 방향으로 전파됨 (프로미스 45.1 에러 처리의 한계 참고)
- 콜 스택의 아래 방향(실행 중인 실행 컨텍스트가 푸시되기 직전에 푸시된 실행 컨텍스트 방향)으로 전파

```Js
const foo = () => {
  throw Error('foo에서 발생한 에러'); // ④
};

const bar = () => {
  foo(); // ③
};

const baz = () => {
  bar(); // ②
};

try {
  baz(); // ①
} catch (err) {
  console.error(err);
}
```

- ①에서 baz 함수를 호출하면 ②에서 bar 함수가 호출되고 ③에서 foo 함수가 호출되고 foo 함수는 ④에서 에러를 throw함
- 이때 foo 함수가 throw한 에러는 호출자에게 전파되어 전역에서 캐치됨
- ![](https://i.imgur.com/cvCi92X.png)

- 이처럼 throw된 에러를 캐치하지 않으면 호출자 방향으로 전파되고, 어디에서도 캐치하지 않는다면 프로그램은 강제 종료된다
- ⚠️ 주의: 비동기 함수인 setTimeout이나 프로미스 후속 처리 메서드의 콜백 함수는 호출자가 없어 에러를 전파할 호출자가 존재하지 않는다
